<mujoco model="Simple Pendulum">
    <asset>
        <texture type="skybox" builtin="gradient" rgb1="0.3 0.5 0.7" rgb2="0 0 0" width="512" height="3072"/>
        <texture type="2d" name="groundplane" builtin="checker" mark="edge" rgb1="0.2 0.3 0.4" rgb2="0.1 0.2 0.3"
        markrgb="0.8 0.8 0.8" width="300" height="300"/>
        <material name="groundplane" texture="groundplane" texuniform="true" texrepeat="5 5" reflectance="0.2"/>
    </asset>
    
    <visual>
        <global offheight="700" offwidth="900" fovy="50" elevation="-30"/>
        <quality offsamples="8"/>
        <headlight diffuse="0.6 0.6 0.6" ambient="0.3 0.3 0.3" specular="0 0 0"/>
        <rgba haze="0.15 0.25 0.35 1"/>
    </visual>
    
    <statistic center="0 0 0.6"/>
    
    <worldbody>
        <light name="light" pos="0 0 2" dir="0 0 -1" castshadow="true" directional="false"/>
        <geom name="floor" size="0 0 .125" type="plane" material="groundplane" conaffinity="15" condim="3"/>
        
        <body name="pendulum" pos="0 0 1">
            <joint name="hinge" type="hinge" pos="0 0 0" axis="0 1 0" damping="3.5"/>
            <geom name="pole" type="cylinder" pos="0 0 -0.25" size="0.02 0.25" mass="0.5" rgba="1.0 0.5 0.1 1"/>
            <geom name="mass" type="sphere" pos="0 0 -0.6" size="0.1" mass="5" rgba="1.0 0.5 0.1 1"/>
        </body>
    </worldbody>
    
    <actuator>
        <motor joint="hinge" name="torque" gear="1" ctrllimited="true" ctrlrange="-25 25"/>
    </actuator>
</mujoco>